Workbook
Name Tableau: Tableau1[]

Sheet Tableau recherche
A1: Région | B1: Département | C1: N° Département | D1: Rue | E1: Code Postal | F1: Ville | G1: Adresse | H1: Lien Google Maps | I1: Emplacement | J1: Typologie | K1: Nature | L1: Durée du bail | M1: Cession / Droit au bail | N1: Numéro de lot | O1: Surface GLA | P1: Répartition surface GLA | Q1: Surface maximale | R1: Surface utile | S1: Répartition surface utile | T1: Loyer annuel | U1: Loyer Mensuel | V1: Loyer €/m² | W1: Loyer variable | X1: Charges annuelles | Y1: Charges Mensuelles | Z1: Charges €/m² | AA1: Taxe foncière | AB1: Taxe foncière €/m² | AC1: Marketing | AD1: Marketing €/m² | AE1: Total (L+C+M) | AF1: Dépôt de garantie | AG1: GAPD | AH1: Gestion | AI1: Etat de livraison | AJ1: Extraction | AK1: Restauration | AL1: Environnement Commercial | AM1: Commentaires | AN1: Honoraires de rédaction | AO1: Honoraires commerciaux | AP1: Latitude | AQ1: Longitude | AR1: Référence annonce | AS1: Photos annonce | AT1: Actif | AU1: Valeur BP | AV1: Contact | AW1: Page Web | AX1: Date d'ajout
A2: =VLOOKUP(Tableau1[[#This Row],[N° Département]],Feuil1!$C$6:$E$106,3) -> Nouvelle-Aquitaine | B2: =VLOOKUP(Tableau1[[#This Row],[N° Département]],Feuil1!$C$6:$E$106,2) -> Charente | C2: =LEFT(Tableau1[[#This Row],[Code Postal]],2)*1 -> 16 | D2: 53 Rue Hergé | E2: 16000 | F2: Angoulême | G2: =Tableau1[[#This Row],[Rue]]&CHAR(10)&Tableau1[[#This Row],[Code Postal]]&" - "&Tableau1[[#This Row],[Ville]] -> 53 Rue Hergé 16000 - Angoulême | H2: https://www.google.com/maps/place/53+Rue+Herg%C3%A9,+16000+Angoul%C3%Aame | I2: Centre Ville | J2: Pied d'immeuble | K2: / | M2: / | N2: / | O2: 451 | P2: 357 + 40 + 21 + 31 | Q2: / | R2: 423 | S2: 342 + 34 + 17 + 28 | T2: =Tableau1[[#This Row],[Loyer €/m²]]*Tableau1[[#This Row],[Surface GLA]] -> 67650 | U2: =IFERROR(Tableau1[[#This Row],[Loyer annuel]]/12,"") -> 5637.5 | V2: 150 | W2: / | X2: =Tableau1[[#This Row],[Charges €/m²]]*Tableau1[[#This Row],[Surface GLA]] -> 12177 | Y2: =IFERROR(Tableau1[[#This Row],[Charges annuelles]]/12,"") -> 1014.75 | Z2: 27 | AA2: =IFERROR(Tableau1[[#This Row],[Taxe foncière €/m²]]*Tableau1[[#This Row],[Surface GLA]],) -> 0 | AB2: / | AC2: =IFERROR(Tableau1[[#This Row],[Marketing €/m²]]*Tableau1[[#This Row],[Surface GLA]],) -> 0 | AD2: / | AE2: =IFERROR(Tableau1[[#This Row],[Loyer annuel]]+Tableau1[[#This Row],[Charges annuelles]]+Tableau1[[#This Row],[Taxe foncière]]+Tableau1[[#This Row],[Marketing]],"") -> 79827 | AF2: / | AG2: / | AH2: / | AI2: En l'état du précédent locataire | AJ2: A étudier | AK2: Chaude et froide | AL2: Foot Locker, Free, SFR, Avril Cosmétique, Tamaris, Devred, Damart, American Vintage, Restauration | AM2: En plein centre-ville. Ancien Sephora. RDC + 3 niveaux. Taxes comprises | AO2: 30% du loyer facial avec un minimum de 15 000 € HT | AP2: 45.648526 | AQ2: 0.158468 | AR2: 1 | AS2: https://pub-843c46afc4cb41489909bce00c9b143d.r2.dev/1%20-%20Angoul%C3%AAme/1.jpg; https://pub-843c46afc4cb41489909bce00c9b143d.r2.dev/1%20-%20Angoul%C3%AAme/2.jpg; https://pub-843c46afc4cb41489909bce00c9b143d.r2.dev/1%20-%20Angoul%C3%AAme/3.jpg; https://pub-843c46afc4cb41489909bce00c9b143d.r2.dev/1%20-%20Angoul%C3%AAme/4%20ANGOULEME%207%20-%20RC%20SEPHORA.jpg; https://pub-843c46afc4cb41489909bce00c9b143d.r2.dev/1%20-%20Angoul%C3%AAme/5%20ANGOULEME%207%20-%201er%20Etage%2053-55%20rue%20herg%C3%A9.jpg; https://pub-843c46afc4cb41489909bce00c9b143d.r2.dev/1%20-%20Angoul%C3%AAme/6%20ANGOULEME%207%20-%202e%20Etage%2053-55%20rue%20herg%C3%A9.jpg; https://pub-843c46afc4cb41489909bce00c9b143d.r2.dev/1%20-%20Angoul%C3%AAme/7%20ANGOULEME%207%20-%203e%20Etage%2053-55%20rue%20herg%C3%A9.jpg | AT2: Oui | AU2: 120 €/m² = 50 760 € | AV2: Praemia
A3: =VLOOKUP(Tableau1[[#This Row],[N° Département]],Feuil1!$C$6:$E$106,3) -> Bourgogne-Franche-Comté | B3: =VLOOKUP(Tableau1[[#This Row],[N° Département]],Feuil1!$C$6:$E$106,2) -> Doubs | C3: =LEFT(Tableau1[[#This Row],[Code Postal]],2)*1 -> 25 | D3: 44 Grande Rue | E3: 25000 | F3: Besançon | G3: =Tableau1[[#This Row],[Rue]]&CHAR(10)&Tableau1[[#This Row],[Code Postal]]&" - "&Tableau1[[#This Row],[Ville]] -> 44 Grande Rue 25000 - Besançon | H3: https://www.google.com/maps/place/44+Grande+Rue,+25000+Besan%C3%A7on | I3: Centre Ville | J3: Pied d'immeuble | K3: / | M3: / | N3: / | O3: 325 | P3: 214 (SS) + 110 | Q3: / | R3: / | S3: / | T3: =Tableau1[[#This Row],[Loyer €/m²]]*Tableau1[[#This Row],[Surface GLA]] -> 42250 | U3: =IFERROR(Tableau1[[#This Row],[Loyer annuel]]/12,"") -> 3520.8333 | V3: 130 | W3: / | X3: =Tableau1[[#This Row],[Charges €/m²]]*Tableau1[[#This Row],[Surface GLA]] -> 8450 | Y3: =IFERROR(Tableau1[[#This Row],[Charges annuelles]]/12,"") -> 704.16667 | Z3: 26 | AA3: =IFERROR(Tableau1[[#This Row],[Taxe foncière €/m²]]*Tableau1[[#This Row],[Surface GLA]],) -> 0 | AB3: / | AC3: =IFERROR(Tableau1[[#This Row],[Marketing €/m²]]*Tableau1[[#This Row],[Surface GLA]],) -> 0 | AD3: / | AE3: =IFERROR(Tableau1[[#This Row],[Loyer annuel]]+Tableau1[[#This Row],[Charges annuelles]]+Tableau1[[#This Row],[Taxe foncière]]+Tableau1[[#This Row],[Marketing]],"") -> 50700 | AF3: / | AG3: / | AH3: / | AI3: En l'état du précédent locataire | AJ3: Non | AK3: Froide | AL3: Avril Cosmétique, Générale d'Optique, Darjeeling, Pimkie, Promod, Calzedonia, Eram, SFR, Le Comptoir de Mathilde, Restauration | AM3: Ancien cabinet médical. Local voisin de Bagelstein. Taxes comprises | AO3: 30% du loyer facial avec un minimum de 15 000 € HT | AP3: 47.238162 | AQ3: 6.0234543 | AR3: 2 | AS3: https://pub-843c46afc4cb41489909bce00c9b143d.r2.dev/2%20-%20Besan%C3%A7on/1.jpg; https://pub-843c46afc4cb41489909bce00c9b143d.r2.dev/2%20-%20Besan%C3%A7on/2.jpg; https://pub-843c46afc4cb41489909bce00c9b143d.r2.dev/2%20-%20Besan%C3%A7on/3.jpg; https://pub-843c46afc4cb41489909bce00c9b143d.r2.dev/2%20-%20Besan%C3%A7on/4%20Plan%20RDC.jpg; https://pub-843c46afc4cb41489909bce00c9b143d.r2.dev/2%20-%20Besan%C3%A7on/5%20Plan%20R-1.jpg | AT3: Oui | AU3: 100 €/m² = 32 500 € | AV3: Praemia
A4: =VLOOKUP(Tableau1[[#This Row],[N° Département]],Feuil1!$C$6:$E$106,3) -> Centre-Val de Loire | B4: =VLOOKUP(Tableau1[[#This Row],[N° Département]],Feuil1!$C$6:$E$106,2) -> Loir-et-Cher | C4: =LEFT(Tableau1[[#This Row],[Code Postal]],2)*1 -> 41 | D4: 90 Rue du Commerce | E4: 41000 | F4: Blois | G4: =Tableau1[[#This Row],[Rue]]&CHAR(10)&Tableau1[[#This Row],[Code Postal]]&" - "&Tableau1[[#This Row],[Ville]] -> 90 Rue du Commerce 41000 - Blois | H4: https://www.google.com/maps/place/90+Rue+du+Commerce,+41000+Blois | I4: Centre Ville | J4: Pied d'immeuble | K4: / | M4: / | N4: / | O4: 264 | P4: 205 + 59 | Q4: / | R4: 244 | S4: 190 + 54 | T4: =Tableau1[[#This Row],[Loyer €/m²]]*Tableau1[[#This Row],[Surface GLA]] -> 92400 | U4: =IFERROR(Tableau1[[#This Row],[Loyer annuel]]/12,"") -> 7700 | V4: 350 | W4: / | X4: =Tableau1[[#This Row],[Charges €/m²]]*Tableau1[[#This Row],[Surface GLA]] -> 12408 | Y4: =IFERROR(Tableau1[[#This Row],[Charges annuelles]]/12,"") -> 1034 | Z4: 47 | AA4: =IFERROR(Tableau1[[#This Row],[Taxe foncière €/m²]]*Tableau1[[#This Row],[Surface GLA]],) -> 0 | AB4: / | AC4: =IFERROR(Tableau1[[#This Row],[Marketing €/m²]]*Tableau1[[#This Row],[Surface GLA]],) -> 0 | AD4: / | AE4: =IFERROR(Tableau1[[#This Row],[Loyer annuel]]+Tableau1[[#This Row],[Charges annuelles]]+Tableau1[[#This Row],[Taxe foncière]]+Tableau1[[#This Row],[Marketing]],"") -> 104808 | AF4: / | AG4: / | AH4: / | AI4: En l'état du précédent locataire | AJ4: Non | AK4: Froide | AL4: My Candle Shop, Naf Naf, Petit Bateau, Armand Thierry, Maison 123, Jott, Calzedonia, Caroll, Pimkie, Restauration | AM4: Ancien Etam. Local en parfait état, utilisé en BDD. Verrière intérieur. Taxes comprises | AO4: 30% du loyer facial avec un minimum de 15 000 € HT | AP4: 47.586994 | AQ4: 1.331958 | AR4: 3 | AS4: https://pub-843c46afc4cb41489909bce00c9b143d.r2.dev/3%20-%20Blois/1.jpg; https://pub-843c46afc4cb41489909bce00c9b143d.r2.dev/3%20-%20Blois/2.jpg; https://pub-843c46afc4cb41489909bce00c9b143d.r2.dev/3%20-%20Blois/3.jpg; https://pub-843c46afc4cb41489909bce00c9b143d.r2.dev/3%20-%20Blois/4.jpg; https://pub-843c46afc4cb41489909bce00c9b143d.r2.dev/3%20-%20Blois/5%20Plan%20RDC.jpg; https://pub-843c46afc4cb41489909bce00c9b143d.r2.dev/3%20-%20Blois/6%20Plan%20R%2B1.jpg | AT4: Oui | AU4: 300 €/m² = 73 500 € | AV4: Praemia
A5: =VLOOKUP(Tableau1[[#This Row],[N° Département]],Feuil1!$C$6:$E$106,3) -> Bourgogne-Franche-Comté | B5: =VLOOKUP(Tableau1[[#This Row],[N° Département]],Feuil1!$C$6:$E$106,2) -> Doubs | C5: =LEFT(Tableau1[[#This Row],[Code Postal]],2)*1 -> 25 | D5: 7 Rue de Sochaux | E5: 25400 | F5: Exincourt | G5: =Tableau1[[#This Row],[Rue]]&CHAR(10)&Tableau1[[#This Row],[Code Postal]]&" - "&Tableau1[[#This Row],[Ville]] -> 7 Rue de Sochaux 25400 - Exincourt | H5: https://maps.app.goo.gl/YuAJQRM2HM3gYVyJ6 | I5: Périphérie | J5: Boîte | K5: / | M5: / | N5: / | O5: 9030 | P5: 2 999 (SS) + 2 978 + 2981 + 72 (mezz) | Q5: / | R5: 8628 | S5: 2 843 (SS) + 2 870 + 2 871 (R+1) + 44 (mezz) | T5: =Tableau1[[#This Row],[Loyer €/m²]]*Tableau1[[#This Row],[Surface GLA]] -> 451500 | U5: =IFERROR(Tableau1[[#This Row],[Loyer annuel]]/12,"") -> 37625 | V5: 50 | W5: / | X5: =Tableau1[[#This Row],[Charges €/m²]]*Tableau1[[#This Row],[Surface GLA]] -> 90300 | Y5: =IFERROR(Tableau1[[#This Row],[Charges annuelles]]/12,"") -> 7525 | Z5: 10 | AA5: =IFERROR(Tableau1[[#This Row],[Taxe foncière €/m²]]*Tableau1[[#This Row],[Surface GLA]],) -> 0 | AB5: / | AC5: =IFERROR(Tableau1[[#This Row],[Marketing €/m²]]*Tableau1[[#This Row],[Surface GLA]],) -> 0 | AD5: / | AE5: =IFERROR(Tableau1[[#This Row],[Loyer annuel]]+Tableau1[[#This Row],[Charges annuelles]]+Tableau1[[#This Row],[Taxe foncière]]+Tableau1[[#This Row],[Marketing]],"") -> 541800 | AF5: / | AG5: / | AH5: / | AI5: En l'état du précédent locataire | AJ5: A étudier | AK5: Chaude et froide | AL5: Ma Jardinerie, Electro Dépôt, Centrakor, La Boucherie, Kya | AM5: Ancien Maison Depôt. Quai de livraison et monte-charge. Taxes comprises | AO5: 30% du loyer facial avec un minimum de 15 000 € HT | AP5: 47.505019 | AQ5: 6.844836 | AR5: 4 | AS5: https://pub-843c46afc4cb41489909bce00c9b143d.r2.dev/4%20-%20Exincourt/1.jpg; https://pub-843c46afc4cb41489909bce00c9b143d.r2.dev/4%20-%20Exincourt/2.jpg; https://pub-843c46afc4cb41489909bce00c9b143d.r2.dev/4%20-%20Exincourt/3%20Plan%20R-1.jpg; https://pub-843c46afc4cb41489909bce00c9b143d.r2.dev/4%20-%20Exincourt/4%20Plan%20RDC.jpg; https://pub-843c46afc4cb41489909bce00c9b143d.r2.dev/4%20-%20Exincourt/5%20Plan%20R%2B1.jpg | AT5: Oui | AU5: 50 €/m² = 431 400 € | AV5: Praemia
A6: =VLOOKUP(Tableau1[[#This Row],[N° Département]],Feuil1!$C$6:$E$106,3) -> Normandie | B6: =VLOOKUP(Tableau1[[#This Row],[N° Département]],Feuil1!$C$6:$E$106,2) -> Calvados | C6: =LEFT(Tableau1[[#This Row],[Code Postal]],2)*1 -> 14 | D6: 103 Le Val | E6: 14200 | F6: Hérouville-Saint-Clair | G6: =Tableau1[[#This Row],[Rue]]&CHAR(10)&Tableau1[[#This Row],[Code Postal]]&" - "&Tableau1[[#This Row],[Ville]] -> 103 Le Val 14200 - Hérouville-Saint-Clair | H6: https://maps.app.goo.gl/yRNFdK1p6sWPThzm7 | I6: Périphérie | J6: Centre Commercial | K6: / | M6: / | N6: B2 | O6: 179 | P6: / | Q6: / | R6: / | S6: / | T6: =Tableau1[[#This Row],[Loyer €/m²]]*Tableau1[[#This Row],[Surface GLA]] -> 71600 | U6: =IFERROR(Tableau1[[#This Row],[Loyer annuel]]/12,"") -> 5966.6667 | V6: 400 | W6: / | X6: =Tableau1[[#This Row],[Charges €/m²]]*Tableau1[[#This Row],[Surface GLA]] -> 13067 | Y6: =IFERROR(Tableau1[[#This Row],[Charges annuelles]]/12,"") -> 1088.9167 | Z6: 73 | AA6: =IFERROR(Tableau1[[#This Row],[Taxe foncière €/m²]]*Tableau1[[#This Row],[Surface GLA]],) -> 4296 | AB6: 24 | AC6: =IFERROR(Tableau1[[#This Row],[Marketing €/m²]]*Tableau1[[#This Row],[Surface GLA]],) -> 3759 | AD6: 21 | AE6: =IFERROR(Tableau1[[#This Row],[Loyer annuel]]+Tableau1[[#This Row],[Charges annuelles]]+Tableau1[[#This Row],[Taxe foncière]]+Tableau1[[#This Row],[Marketing]],"") -> 92722 | AF6: / | AG6: / | AH6: 0.025 | AI6: En l'état du précédent locataire | AJ6: Non | AK6: Froide | AL6: Basic Fit, Normal, Micromania, Okaïdi, Marionnaud, Promod, Rougegorge, Mcdonald's | AM6: Flux de 4,4M annuel avec un hyper à 60 M€. 73 boutiques dans la Galerie. | AO6: 30% du loyer facial avec un minimum de 15 000 € HT | AP6: 49.205819 | AQ6: -0.328482 | AR6: 5.1 | AS6: https://pub-843c46afc4cb41489909bce00c9b143d.r2.dev/5.1%20-%20H%C3%A9rouville-Saint-Clair/1.jpg; https://pub-843c46afc4cb41489909bce00c9b143d.r2.dev/5.1%20-%20H%C3%A9rouville-Saint-Clair/2.jpg; https://pub-843c46afc4cb41489909bce00c9b143d.r2.dev/5.1%20-%20H%C3%A9rouville-Saint-Clair/3.jpg; https://pub-843c46afc4cb41489909bce00c9b143d.r2.dev/5.1%20-%20H%C3%A9rouville-Saint-Clair/4.jpg; https://pub-843c46afc4cb41489909bce00c9b143d.r2.dev/5.1%20-%20H%C3%A9rouville-Saint-Clair/5%20B1-B2%20-%20Division%202022%20-%20GO%20Cloison-Pr%C3%A9sentation%20AT%20(1)%20-%20La_Casa_de_la_Carcasas.jpg | AT6: Oui | AU6: Au BP | AV6: Twenty Two
A7: =VLOOKUP(Tableau1[[#This Row],[N° Département]],Feuil1!$C$6:$E$106,3) -> Normandie | B7: =VLOOKUP(Tableau1[[#This Row],[N° Département]],Feuil1!$C$6:$E$106,2) -> Calvados | C7: =LEFT(Tableau1[[#This Row],[Code Postal]],2)*1 -> 14 | D7: 103 Le Val | E7: 14200 | F7: Hérouville-Saint-Clair | G7: =Tableau1[[#This Row],[Rue]]&CHAR(10)&Tableau1[[#This Row],[Code Postal]]&" - "&Tableau1[[#This Row],[Ville]] -> 103 Le Val 14200 - Hérouville-Saint-Clair | H7: https://maps.app.goo.gl/yRNFdK1p6sWPThzm8 | I7: Périphérie | J7: Centre Commercial | K7: / | M7: / | N7: B4 | O7: 159 | P7: / | Q7: / | R7: / | S7: / | T7: =Tableau1[[#This Row],[Loyer €/m²]]*Tableau1[[#This Row],[Surface GLA]] -> 63600 | U7: =IFERROR(Tableau1[[#This Row],[Loyer annuel]]/12,"") -> 5300 | V7: 400 | W7: / | X7: =Tableau1[[#This Row],[Charges €/m²]]*Tableau1[[#This Row],[Surface GLA]] -> 11607 | Y7: =Tableau1[[#This Row],[Charges annuelles]]/12 -> 967.25 | Z7: 73 | AA7: =IFERROR(Tableau1[[#This Row],[Taxe foncière €/m²]]*Tableau1[[#This Row],[Surface GLA]],) -> 3816 | AB7: 24 | AC7: =IFERROR(Tableau1[[#This Row],[Marketing €/m²]]*Tableau1[[#This Row],[Surface GLA]],) -> 3339 | AD7: 21 | AE7: =IFERROR(Tableau1[[#This Row],[Loyer annuel]]+Tableau1[[#This Row],[Charges annuelles]]+Tableau1[[#This Row],[Taxe foncière]]+Tableau1[[#This Row],[Marketing]],"") -> 82362 | AF7: / | AG7: / | AH7: 0.025 | AI7: En l'état du précédent locataire | AJ7: Non | AK7: Froide | AL7: Basic Fit, Normal, Micromania, Okaïdi, Marionnaud, Promod, Rougegorge, Mcdonald's | AM7: Flux de 4,4M annuel avec un hyper à 60 M€. 73 boutiques dans la Galerie. | AO7: 30% du loyer facial avec un minimum de 15 000 € HT | AP7: 49.205645 | AQ7: -0.328361 | AR7: 5.2 | AS7: https://pub-843c46afc4cb41489909bce00c9b143d.r2.dev/5.1%20-%20H%C3%A9rouville-Saint-Clair/1.jpg; https://pub-843c46afc4cb41489909bce00c9b143d.r2.dev/5.1%20-%20H%C3%A9rouville-Saint-Clair/2.jpg; https://pub-843c46afc4cb41489909bce00c9b143d.r2.dev/5.1%20-%20H%C3%A9rouville-Saint-Clair/3.jpg; https://pub-843c46afc4cb41489909bce00c9b143d.r2.dev/5.1%20-%20H%C3%A9rouville-Saint-Clair/4.jpg; https://pub-843c46afc4cb41489909bce00c9b143d.r2.dev/5.2%20-%20H%C3%A9rouville-Saint-Clair/5%20B4%20-%205372-GLA-2019.07.12.jpg | AT7: Oui | AU7: Au BP | AV7: Twenty Two
A8: =VLOOKUP(Tableau1[[#This Row],[N° Département]],Feuil1!$C$6:$E$106,3) -> Normandie | B8: =VLOOKUP(Tableau1[[#This Row],[N° Département]],Feuil1!$C$6:$E$106,2) -> Calvados | C8: =LEFT(Tableau1[[#This Row],[Code Postal]],2)*1 -> 14 | D8: 103 Le Val | E8: 14200 | F8: Hérouville-Saint-Clair | G8: =Tableau1[[#This Row],[Rue]]&CHAR(10)&Tableau1[[#This Row],[Code Postal]]&" - "&Tableau1[[#This Row],[Ville]] -> 103 Le Val 14200 - Hérouville-Saint-Clair | H8: https://maps.app.goo.gl/yRNFdK1p6sWPThzm9 | I8: Périphérie | J8: Centre Commercial | K8: / | M8: / | N8: B6 | O8: 125 | P8: / | Q8: / | R8: / | S8: / | T8: =Tableau1[[#This Row],[Loyer €/m²]]*Tableau1[[#This Row],[Surface GLA]] -> 56250 | U8: =IFERROR(Tableau1[[#This Row],[Loyer annuel]]/12,"") -> 4687.5 | V8: 450 | W8: / | X8: =Tableau1[[#This Row],[Charges €/m²]]*Tableau1[[#This Row],[Surface GLA]] -> 9125 | Y8: =Tableau1[[#This Row],[Charges annuelles]]/12 -> 760.41667 | Z8: 73 | AA8: =IFERROR(Tableau1[[#This Row],[Taxe foncière €/m²]]*Tableau1[[#This Row],[Surface GLA]],) -> 3000 | AB8: 24 | AC8: =IFERROR(Tableau1[[#This Row],[Marketing €/m²]]*Tableau1[[#This Row],[Surface GLA]],) -> 2625 | AD8: 21 | AE8: =IFERROR(Tableau1[[#This Row],[Loyer annuel]]+Tableau1[[#This Row],[Charges annuelles]]+Tableau1[[#This Row],[Taxe foncière]]+Tableau1[[#This Row],[Marketing]],"") -> 71000 | AF8: / | AG8: / | AH8: 0.025 | AI8: En l'état du précédent locataire | AJ8: Non | AK8: Froide | AL8: Basic Fit, Normal, Micromania, Okaïdi, Marionnaud, Promod, Rougegorge, Mcdonald's | AM8: Flux de 4,4M annuel avec un hyper à 60 M€. 73 boutiques dans la Galerie. | AO8: 30% du loyer facial avec un minimum de 15 000 € HT | AP8: 49.206029 | AQ8: -0.328616 | AR8: 5.3 | AS8: https://pub-843c46afc4cb41489909bce00c9b143d.r2.dev/5.1%20-%20H%C3%A9rouville-Saint-Clair/1.jpg; https://pub-843c46afc4cb41489909bce00c9b143d.r2.dev/5.1%20-%20H%C3%A9rouville-Saint-Clair/2.jpg; https://pub-843c46afc4cb41489909bce00c9b143d.r2.dev/5.1%20-%20H%C3%A9rouville-Saint-Clair/3.jpg; https://pub-843c46afc4cb41489909bce00c9b143d.r2.dev/5.1%20-%20H%C3%A9rouville-Saint-Clair/4.jpg; https://pub-843c46afc4cb41489909bce00c9b143d.r2.dev/5.3%20-%20H%C3%A9rouville-Saint-Clair/5%20B6%20-%205372%20-%20GLA-2017.12.04.jpg | AT8: Oui | AU8: Au BP | AV8: Twenty Two
A9: =VLOOKUP(Tableau1[[#This Row],[N° Département]],Feuil1!$C$6:$E$106,3) -> Normandie | B9: =VLOOKUP(Tableau1[[#This Row],[N° Département]],Feuil1!$C$6:$E$106,2) -> Calvados | C9: =LEFT(Tableau1[[#This Row],[Code Postal]],2)*1 -> 14 | D9: 103 Le Val | E9: 14200 | F9: Hérouville-Saint-Clair | G9: =Tableau1[[#This Row],[Rue]]&CHAR(10)&Tableau1[[#This Row],[Code Postal]]&" - "&Tableau1[[#This Row],[Ville]] -> 103 Le Val 14200 - Hérouville-Saint-Clair | H9: https://maps.app.goo.gl/yRNFdK1p6sWPThzm10 | I9: Périphérie | J9: Centre Commercial | K9: / | M9: / | N9: B7 | O9: 156 | P9: / | Q9: 758 | R9: / | S9: / | T9: =Tableau1[[#This Row],[Loyer €/m²]]*Tableau1[[#This Row],[Surface GLA]] -> 62400 | U9: =IFERROR(Tableau1[[#This Row],[Loyer annuel]]/12,"") -> 5200 | V9: 400 | W9: / | X9: =Tableau1[[#This Row],[Charges €/m²]]*Tableau1[[#This Row],[Surface GLA]] -> 11388 | Y9: =Tableau1[[#This Row],[Charges annuelles]]/12 -> 949 | Z9: 73 | AA9: =IFERROR(Tableau1[[#This Row],[Taxe foncière €/m²]]*Tableau1[[#This Row],[Surface GLA]],) -> 3744 | AB9: 24 | AC9: =IFERROR(Tableau1[[#This Row],[Marketing €/m²]]*Tableau1[[#This Row],[Surface GLA]],) -> 3276 | AD9: 21 | AE9: =IFERROR(Tableau1[[#This Row],[Loyer annuel]]+Tableau1[[#This Row],[Charges annuelles]]+Tableau1[[#This Row],[Taxe foncière]]+Tableau1[[#This Row],[Marketing]],"") -> 80808 | AF9: / | AG9: / | AH9: 0.025 | AI9: En l'état du précédent locataire | AJ9: Non | AK9: Froide | AL9: Basic Fit, Normal, Micromania, Okaïdi, Marionnaud, Promod, Rougegorge, Mcdonald's | AM9: Flux de 4,4M annuel avec un hyper à 60 M€. 73 boutiques dans la Galerie. | AO9: 30% du loyer facial avec un minimum de 15 000 € HT | AP9: 49.206122 | AQ9: -0.328394 | AR9: 5.4 | AS9: https://pub-843c46afc4cb41489909bce00c9b143d.r2.dev/5.1%20-%20H%C3%A9rouville-Saint-Clair/1.jpg; https://pub-843c46afc4cb41489909bce00c9b143d.r2.dev/5.1%20-%20H%C3%A9rouville-Saint-Clair/2.jpg; https://pub-843c46afc4cb41489909bce00c9b143d.r2.dev/5.1%20-%20H%C3%A9rouville-Saint-Clair/3.jpg; https://pub-843c46afc4cb41489909bce00c9b143d.r2.dev/5.1%20-%20H%C3%A9rouville-Saint-Clair/4.jpg; https://pub-843c46afc4cb41489909bce00c9b143d.r2.dev/5.4%20-%20H%C3%A9rouville-Saint-Clair/5%20B7%20-%205372-GLA-2019.07.12.jpg | AT9: Oui | AU9: Au BP | AV9: Twenty Two
A10: =VLOOKUP(Tableau1[[#This Row],[N° Département]],Feuil1!$C$6:$E$106,3) -> Normandie | B10: =VLOOKUP(Tableau1[[#This Row],[N° Département]],Feuil1!$C$6:$E$106,2) -> Calvados | C10: =LEFT(Tableau1[[#This Row],[Code Postal]],2)*1 -> 14 | D10: 103 Le Val | E10: 14200 | F10: Hérouville-Saint-Clair | G10: =Tableau1[[#This Row],[Rue]]&CHAR(10)&Tableau1[[#This Row],[Code Postal]]&" - "&Tableau1[[#This Row],[Ville]] -> 103 Le Val 14200 - Hérouville-Saint-Clair | H10: https://maps.app.goo.gl/yRNFdK1p6sWPThzm11 | I10: Périphérie | J10: Centre Commercial | K10: / | M10: / | N10: B9 | O10: 178 | P10: / | Q10: 758 | R10: / | S10: / | T10: =Tableau1[[#This Row],[Loyer €/m²]]*Tableau1[[#This Row],[Surface GLA]] -> 71200 | U10: =IFERROR(Tableau1[[#This Row],[Loyer annuel]]/12,"") -> 5933.3333 | V10: 400 | W10: / | X10: =Tableau1[[#This Row],[Charges €/m²]]*Tableau1[[#This Row],[Surface GLA]] -> 12994 | Y10: =Tableau1[[#This Row],[Charges annuelles]]/12 -> 1082.8333 | Z10: 73 | AA10: =IFERROR(Tableau1[[#This Row],[Taxe foncière €/m²]]*Tableau1[[#This Row],[Surface GLA]],) -> 4272 | AB10: 24 | AC10: =IFERROR(Tableau1[[#This Row],[Marketing €/m²]]*Tableau1[[#This Row],[Surface GLA]],) -> 3738 | AD10: 21 | AE10: =IFERROR(Tableau1[[#This Row],[Loyer annuel]]+Tableau1[[#This Row],[Charges annuelles]]+Tableau1[[#This Row],[Taxe foncière]]+Tableau1[[#This Row],[Marketing]],"") -> 92204 | AF10: / | AG10: / | AH10: 0.025 | AI10: En l'état du précédent locataire | AJ10: Non | AK10: Froide | AL10: Basic Fit, Normal, Micromania, Okaïdi, Marionnaud, Promod, Rougegorge, Mcdonald's | AM10: Flux de 4,4M annuel avec un hyper à 60 M€. 73 boutiques dans la Galerie. | AO10: 30% du loyer facial avec un minimum de 15 000 € HT | AP10: 49.206071 | AQ10: -0.328211 | AR10: 5.5 | AS10: https://pub-843c46afc4cb41489909bce00c9b143d.r2.dev/5.1%20-%20H%C3%A9rouville-Saint-Clair/1.jpg; https://pub-843c46afc4cb41489909bce00c9b143d.r2.dev/5.1%20-%20H%C3%A9rouville-Saint-Clair/2.jpg; https://pub-843c46afc4cb41489909bce00c9b143d.r2.dev/5.1%20-%20H%C3%A9rouville-Saint-Clair/3.jpg; https://pub-843c46afc4cb41489909bce00c9b143d.r2.dev/5.1%20-%20H%C3%A9rouville-Saint-Clair/4.jpg; https://pub-843c46afc4cb41489909bce00c9b143d.r2.dev/5.5%20-%20H%C3%A9rouville-Saint-Clair/5%20B9%20-%205372-GLA-2019.07.12.jpg | AT10: Oui | AU10: Au BP | AV10: Twenty Two
A11: =VLOOKUP(Tableau1[[#This Row],[N° Département]],Feuil1!$C$6:$E$106,3) -> Normandie | B11: =VLOOKUP(Tableau1[[#This Row],[N° Département]],Feuil1!$C$6:$E$106,2) -> Calvados | C11: =LEFT(Tableau1[[#This Row],[Code Postal]],2)*1 -> 14 | D11: 103 Le Val | E11: 14200 | F11: Hérouville-Saint-Clair | G11: =Tableau1[[#This Row],[Rue]]&CHAR(10)&Tableau1[[#This Row],[Code Postal]]&" - "&Tableau1[[#This Row],[Ville]] -> 103 Le Val 14200 - Hérouville-Saint-Clair | H11: https://maps.app.goo.gl/yRNFdK1p6sWPThzm12 | I11: Périphérie | J11: Centre Commercial | K11: / | M11: / | N11: B11 | O11: 253 | P11: / | Q11: 758 | R11: / | S11: / | T11: =Tableau1[[#This Row],[Loyer €/m²]]*Tableau1[[#This Row],[Surface GLA]] -> 88550 | U11: =IFERROR(Tableau1[[#This Row],[Loyer annuel]]/12,"") -> 7379.1667 | V11: 350 | W11: / | X11: =Tableau1[[#This Row],[Charges €/m²]]*Tableau1[[#This Row],[Surface GLA]] -> 18469 | Y11: =Tableau1[[#This Row],[Charges annuelles]]/12 -> 1539.0833 | Z11: 73 | AA11: =IFERROR(Tableau1[[#This Row],[Taxe foncière €/m²]]*Tableau1[[#This Row],[Surface GLA]],) -> 6072 | AB11: 24 | AC11: =IFERROR(Tableau1[[#This Row],[Marketing €/m²]]*Tableau1[[#This Row],[Surface GLA]],) -> 5313 | AD11: 21 | AE11: =IFERROR(Tableau1[[#This Row],[Loyer annuel]]+Tableau1[[#This Row],[Charges annuelles]]+Tableau1[[#This Row],[Taxe foncière]]+Tableau1[[#This Row],[Marketing]],"") -> 118404 | AF11: / | AG11: / | AH11: 0.025 | AI11: En l'état du précédent locataire | AJ11: Non | AK11: Froide | AL11: Basic Fit, Normal, Micromania, Okaïdi, Marionnaud, Promod, Rougegorge, Mcdonald's | AM11: Flux de 4,4M annuel avec un hyper à 60 M€. 73 boutiques dans la Galerie. | AO11: 30% du loyer facial avec un minimum de 15 000 € HT | AP11: 49.206257 | AQ11: -0.327930 | AR11: 5.6 | AS11: https://pub-843c46afc4cb41489909bce00c9b143d.r2.dev/5.1%20-%20H%C3%A9rouville-Saint-Clair/1.jpg; https://pub-843c46afc4cb41489909bce00c9b143d.r2.dev/5.1%20-%20H%C3%A9rouville-Saint-Clair/2.jpg; https://pub-843c46afc4cb41489909bce00c9b143d.r2.dev/5.1%20-%20H%C3%A9rouville-Saint-Clair/3.jpg; https://pub-843c46afc4cb41489909bce00c9b143d.r2.dev/5.1%20-%20H%C3%A9rouville-Saint-Clair/4.jpg; https://pub-843c46afc4cb41489909bce00c9b143d.r2.dev/5.6%20-%20H%C3%A9rouville-Saint-Clair/5%20B11%20(ex%20Cama%C3%AFeu)%20(nouveau%20B69)%20-%205372-GLA-2019.07.12.jpg | AT11: Oui | AU11: Au BP | AV11: Twenty Two
A12: =VLOOKUP(Tableau1[[#This Row],[N° Département]],Feuil1!$C$6:$E$106,3) -> Normandie | B12: =VLOOKUP(Tableau1[[#This Row],[N° Département]],Feuil1!$C$6:$E$106,2) -> Calvados | C12: =LEFT(Tableau1[[#This Row],[Code Postal]],2)*1 -> 14 | D12: 103 Le Val | E12: 14200 | F12: Hérouville-Saint-Clair | G12: =Tableau1[[#This Row],[Rue]]&CHAR(10)&Tableau1[[#This Row],[Code Postal]]&" - "&Tableau1[[#This Row],[Ville]] -> 103 Le Val 14200 - Hérouville-Saint-Clair | H12: https://maps.app.goo.gl/yRNFdK1p6sWPThzm13 | I12: Périphérie | J12: Centre Commercial | K12: / | M12: / | N12: B12 | O12: 171 | P12: / | Q12: 758 | R12: / | S12: / | T12: =Tableau1[[#This Row],[Loyer €/m²]]*Tableau1[[#This Row],[Surface GLA]] -> 68400 | U12: =IFERROR(Tableau1[[#This Row],[Loyer annuel]]/12,"") -> 5700 | V12: 400 | W12: / | X12: =Tableau1[[#This Row],[Charges €/m²]]*Tableau1[[#This Row],[Surface GLA]] -> 12483 | Y12: =Tableau1[[#This Row],[Charges annuelles]]/12 -> 1040.25 | Z12: 73 | AA12: =IFERROR(Tableau1[[#This Row],[Taxe foncière €/m²]]*Tableau1[[#This Row],[Surface GLA]],) -> 4104 | AB12: 24 | AC12: =IFERROR(Tableau1[[#This Row],[Marketing €/m²]]*Tableau1[[#This Row],[Surface GLA]],) -> 3591 | AD12: 21 | AE12: =IFERROR(Tableau1[[#This Row],[Loyer annuel]]+Tableau1[[#This Row],[Charges annuelles]]+Tableau1[[#This Row],[Taxe foncière]]+Tableau1[[#This Row],[Marketing]],"") -> 88578 | AF12: / | AG12: / | AH12: 0.025 | AI12: En l'état du précédent locataire | AJ12: Non | AK12: Froide | AL12: Basic Fit, Normal, Micromania, Okaïdi, Marionnaud, Promod, Rougegorge, Mcdonald's | AM12: Flux de 4,4M annuel avec un hyper à 60 M€. 73 boutiques dans la Galerie. | AO12: 30% du loyer facial avec un minimum de 15 000 € HT | AP12: 49.206164 | AQ12: -0.327884 | AR12: 5.7 | AS12: https://pub-843c46afc4cb41489909bce00c9b143d.r2.dev/5.1%20-%20H%C3%A9rouville-Saint-Clair/1.jpg; https://pub-843c46afc4cb41489909bce00c9b143d.r2.dev/5.1%20-%20H%C3%A9rouville-Saint-Clair/2.jpg; https://pub-843c46afc4cb41489909bce00c9b143d.r2.dev/5.1%20-%20H%C3%A9rouville-Saint-Clair/3.jpg; https://pub-843c46afc4cb41489909bce00c9b143d.r2.dev/5.1%20-%20H%C3%A9rouville-Saint-Clair/4.jpg; https://pub-843c46afc4cb41489909bce00c9b143d.r2.dev/5.7%20-%20H%C3%A9rouville-Saint-Clair/5%20B12%20-%205372-GLA-2019.07.12.jpg | AT12: Oui | AU12: Au BP | AV12: Twenty Two
A13: =VLOOKUP(Tableau1[[#This Row],[N° Département]],Feuil1!$C$6:$E$106,3) -> Normandie | B13: =VLOOKUP(Tableau1[[#This Row],[N° Département]],Feuil1!$C$6:$E$106,2) -> Calvados | C13: =LEFT(Tableau1[[#This Row],[Code Postal]],2)*1 -> 14 | D13: 103 Le Val | E13: 14200 | F13: Hérouville-Saint-Clair | G13: =Tableau1[[#This Row],[Rue]]&CHAR(10)&Tableau1[[#This Row],[Code Postal]]&" - "&Tableau1[[#This Row],[Ville]] -> 103 Le Val 14200 - Hérouville-Saint-Clair | H13: https://maps.app.goo.gl/yRNFdK1p6sWPThzm14 | I13: Périphérie | J13: Centre Commercial | K13: / | M13: / | N13: B14A | O13: 200 | P13: / | Q13: 305 | R13: / | S13: / | T13: =Tableau1[[#This Row],[Loyer €/m²]]*Tableau1[[#This Row],[Surface GLA]] -> 70000 | U13: =IFERROR(Tableau1[[#This Row],[Loyer annuel]]/12,"") -> 5833.3333 | V13: 350 | W13: / | X13: =Tableau1[[#This Row],[Charges €/m²]]*Tableau1[[#This Row],[Surface GLA]] -> 14600 | Y13: =Tableau1[[#This Row],[Charges annuelles]]/12 -> 1216.6667 | Z13: 73 | AA13: =IFERROR(Tableau1[[#This Row],[Taxe foncière €/m²]]*Tableau1[[#This Row],[Surface GLA]],) -> 4800 | AB13: 24 | AC13: =IFERROR(Tableau1[[#This Row],[Marketing €/m²]]*Tableau1[[#This Row],[Surface GLA]],) -> 4200 | AD13: 21 | AE13: =IFERROR(Tableau1[[#This Row],[Loyer annuel]]+Tableau1[[#This Row],[Charges annuelles]]+Tableau1[[#This Row],[Taxe foncière]]+Tableau1[[#This Row],[Marketing]],"") -> 93600 | AF13: / | AG13: / | AH13: 0.025 | AI13: En l'état du précédent locataire | AJ13: Non | AK13: Froide | AL13: Basic Fit, Normal, Micromania, Okaïdi, Marionnaud, Promod, Rougegorge, Mcdonald's | AM13: Flux de 4,4M annuel avec un hyper à 60 M€. 73 boutiques dans la Galerie. | AO13: 30% du loyer facial avec un minimum de 15 000 € HT | AP13: 49.206310 | AQ13: -0.327702 | AR13: 5.8 | AS13: https://pub-843c46afc4cb41489909bce00c9b143d.r2.dev/5.1%20-%20H%C3%A9rouville-Saint-Clair/1.jpg; https://pub-843c46afc4cb41489909bce00c9b143d.r2.dev/5.1%20-%20H%C3%A9rouville-Saint-Clair/2.jpg; https://pub-843c46afc4cb41489909bce00c9b143d.r2.dev/5.1%20-%20H%C3%A9rouville-Saint-Clair/3.jpg; https://pub-843c46afc4cb41489909bce00c9b143d.r2.dev/5.1%20-%20H%C3%A9rouville-Saint-Clair/4.jpg; https://pub-843c46afc4cb41489909bce00c9b143d.r2.dev/5.8%20-%20H%C3%A9rouville-Saint-Clair/5%20B14A%20-%205372-GLA-2019.07.12.jpg | AT13: Oui | AU13: Au BP | AV13: Twenty Two
A14: =VLOOKUP(Tableau1[[#This Row],[N° Département]],Feuil1!$C$6:$E$106,3) -> Normandie | B14: =VLOOKUP(Tableau1[[#This Row],[N° Département]],Feuil1!$C$6:$E$106,2) -> Calvados | C14: =LEFT(Tableau1[[#This Row],[Code Postal]],2)*1 -> 14 | D14: 103 Le Val | E14: 14200 | F14: Hérouville-Saint-Clair | G14: =Tableau1[[#This Row],[Rue]]&CHAR(10)&Tableau1[[#This Row],[Code Postal]]&" - "&Tableau1[[#This Row],[Ville]] -> 103 Le Val 14200 - Hérouville-Saint-Clair | H14: https://maps.app.goo.gl/yRNFdK1p6sWPThzm15 | I14: Périphérie | J14: Centre Commercial | K14: / | M14: / | N14: B14B | O14: 105 | P14: / | Q14: 305 | R14: / | S14: / | T14: =Tableau1[[#This Row],[Loyer €/m²]]*Tableau1[[#This Row],[Surface GLA]] -> 47250 | U14: =IFERROR(Tableau1[[#This Row],[Loyer annuel]]/12,"") -> 3937.5 | V14: 450 | W14: / | X14: =Tableau1[[#This Row],[Charges €/m²]]*Tableau1[[#This Row],[Surface GLA]] -> 7665 | Y14: =Tableau1[[#This Row],[Charges annuelles]]/12 -> 638.75 | Z14: 73 | AA14: =IFERROR(Tableau1[[#This Row],[Taxe foncière €/m²]]*Tableau1[[#This Row],[Surface GLA]],) -> 2520 | AB14: 24 | AC14: =IFERROR(Tableau1[[#This Row],[Marketing €/m²]]*Tableau1[[#This Row],[Surface GLA]],) -> 2205 | AD14: 21 | AE14: =IFERROR(Tableau1[[#This Row],[Loyer annuel]]+Tableau1[[#This Row],[Charges annuelles]]+Tableau1[[#This Row],[Taxe foncière]]+Tableau1[[#This Row],[Marketing]],"") -> 59640 | AF14: / | AG14: / | AH14: 0.025 | AI14: En l'état du précédent locataire | AJ14: Non | AK14: Froide | AL14: Basic Fit, Normal, Micromania, Okaïdi, Marionnaud, Promod, Rougegorge, Mcdonald's | AM14: Flux de 4,4M annuel avec un hyper à 60 M€. 73 boutiques dans la Galerie. | AO14: 30% du loyer facial avec un minimum de 15 000 € HT | AP14: 49.206238 | AQ14: -0.327648 | AR14: 5.9 | AS14: https://pub-843c46afc4cb41489909bce00c9b143d.r2.dev/5.1%20-%20H%C3%A9rouville-Saint-Clair/1.jpg; https://pub-843c46afc4cb41489909bce00c9b143d.r2.dev/5.1%20-%20H%C3%A9rouville-Saint-Clair/2.jpg; https://pub-843c46afc4cb41489909bce00c9b143d.r2.dev/5.1%20-%20H%C3%A9rouville-Saint-Clair/3.jpg; https://pub-843c46afc4cb41489909bce00c9b143d.r2.dev/5.1%20-%20H%C3%A9rouville-Saint-Clair/4.jpg; https://pub-843c46afc4cb41489909bce00c9b143d.r2.dev/5.9%20-%20H%C3%A9rouville-Saint-Clair/5%20B14B%20-%205372-GLA-2019.07.12.jpg | AT14: Oui | AU14: Au BP | AV14: Twenty Two
A15: =VLOOKUP(Tableau1[[#This Row],[N° Département]],Feuil1!$C$6:$E$106,3) -> Normandie | B15: =VLOOKUP(Tableau1[[#This Row],[N° Département]],Feuil1!$C$6:$E$106,2) -> Calvados | C15: =LEFT(Tableau1[[#This Row],[Code Postal]],2)*1 -> 14 | D15: 103 Le Val | E15: 14200 | F15: Hérouville-Saint-Clair | G15: =Tableau1[[#This Row],[Rue]]&CHAR(10)&Tableau1[[#This Row],[Code Postal]]&" - "&Tableau1[[#This Row],[Ville]] -> 103 Le Val 14200 - Hérouville-Saint-Clair | H15: https://maps.app.goo.gl/yRNFdK1p6sWPThzm16 | I15: Périphérie | J15: Centre Commercial | K15: / | M15: / | N15: B21 | O15: 51 | P15: / | Q15: 166 | R15: / | S15: / | T15: =Tableau1[[#This Row],[Loyer €/m²]]*Tableau1[[#This Row],[Surface GLA]] -> 25500 | U15: =IFERROR(Tableau1[[#This Row],[Loyer annuel]]/12,"") -> 2125 | V15: 500 | W15: / | X15: =Tableau1[[#This Row],[Charges €/m²]]*Tableau1[[#This Row],[Surface GLA]] -> 3723 | Y15: =Tableau1[[#This Row],[Charges annuelles]]/12 -> 310.25 | Z15: 73 | AA15: =IFERROR(Tableau1[[#This Row],[Taxe foncière €/m²]]*Tableau1[[#This Row],[Surface GLA]],) -> 1224 | AB15: 24 | AC15: =IFERROR(Tableau1[[#This Row],[Marketing €/m²]]*Tableau1[[#This Row],[Surface GLA]],) -> 1071 | AD15: 21 | AE15: =IFERROR(Tableau1[[#This Row],[Loyer annuel]]+Tableau1[[#This Row],[Charges annuelles]]+Tableau1[[#This Row],[Taxe foncière]]+Tableau1[[#This Row],[Marketing]],"") -> 31518 | AF15: / | AG15: / | AH15: 0.025 | AI15: En l'état du précédent locataire | AJ15: Non | AK15: Froide | AL15: Basic Fit, Normal, Micromania, Okaïdi, Marionnaud, Promod, Rougegorge, Mcdonald's | AM15: Flux de 4,4M annuel avec un hyper à 60 M€. 73 boutiques dans la Galerie. | AO15: 30% du loyer facial avec un minimum de 15 000 € HT | AP15: 49.206083 | AQ15: -0.327479 | AR15: 5.10 | AS15: https://pub-843c46afc4cb41489909bce00c9b143d.r2.dev/5.1%20-%20H%C3%A9rouville-Saint-Clair/1.jpg; https://pub-843c46afc4cb41489909bce00c9b143d.r2.dev/5.1%20-%20H%C3%A9rouville-Saint-Clair/2.jpg; https://pub-843c46afc4cb41489909bce00c9b143d.r2.dev/5.1%20-%20H%C3%A9rouville-Saint-Clair/3.jpg; https://pub-843c46afc4cb41489909bce00c9b143d.r2.dev/5.1%20-%20H%C3%A9rouville-Saint-Clair/4.jpg; https://pub-843c46afc4cb41489909bce00c9b143d.r2.dev/5.10%20-%20H%C3%A9rouville-Saint-Clair/5%20B21%20-%205372%20-%20GLA-2017.12.04.jpg | AT15: Oui | AU15: Au BP | AV15: Twenty Two
A16: =VLOOKUP(Tableau1[[#This Row],[N° Département]],Feuil1!$C$6:$E$106,3) -> Normandie | B16: =VLOOKUP(Tableau1[[#This Row],[N° Département]],Feuil1!$C$6:$E$106,2) -> Calvados | C16: =LEFT(Tableau1[[#This Row],[Code Postal]],2)*1 -> 14 | D16: 103 Le Val | E16: 14200 | F16: Hérouville-Saint-Clair | G16: =Tableau1[[#This Row],[Rue]]&CHAR(10)&Tableau1[[#This Row],[Code Postal]]&" - "&Tableau1[[#This Row],[Ville]] -> 103 Le Val 14200 - Hérouville-Saint-Clair | H16: https://maps.app.goo.gl/yRNFdK1p6sWPThzm17 | I16: Périphérie | J16: Centre Commercial | K16: / | M16: / | N16: B23B | O16: 115 | P16: / | Q16: 166 | R16: / | S16: / | T16: =Tableau1[[#This Row],[Loyer €/m²]]*Tableau1[[#This Row],[Surface GLA]] -> 51750 | U16: =IFERROR(Tableau1[[#This Row],[Loyer annuel]]/12,"") -> 4312.5 | V16: 450 | W16: / | X16: =Tableau1[[#This Row],[Charges €/m²]]*Tableau1[[#This Row],[Surface GLA]] -> 8395 | Y16: =Tableau1[[#This Row],[Charges annuelles]]/12 -> 699.58333 | Z16: 73 | AA16: =IFERROR(Tableau1[[#This Row],[Taxe foncière €/m²]]*Tableau1[[#This Row],[Surface GLA]],) -> 2760 | AB16: 24 | AC16: =IFERROR(Tableau1[[#This Row],[Marketing €/m²]]*Tableau1[[#This Row],[Surface GLA]],) -> 2415 | AD16: 21 | AE16: =IFERROR(Tableau1[[#This Row],[Loyer annuel]]+Tableau1[[#This Row],[Charges annuelles]]+Tableau1[[#This Row],[Taxe foncière]]+Tableau1[[#This Row],[Marketing]],"") -> 65320 | AF16: / | AG16: / | AH16: 0.025 | AI16: En l'état du précédent locataire | AJ16: Non | AK16: Froide | AL16: Basic Fit, Normal, Micromania, Okaïdi, Marionnaud, Promod, Rougegorge, Mcdonald's | AM16: Flux de 4,4M annuel avec un hyper à 60 M€. 73 boutiques dans la Galerie. | AO16: 30% du loyer facial avec un minimum de 15 000 € HT | AP16: 49.206083 | AQ16: -0.327589 | AR16: 5.11 | AS16: https://pub-843c46afc4cb41489909bce00c9b143d.r2.dev/5.1%20-%20H%C3%A9rouville-Saint-Clair/1.jpg; https://pub-843c46afc4cb41489909bce00c9b143d.r2.dev/5.1%20-%20H%C3%A9rouville-Saint-Clair/2.jpg; https://pub-843c46afc4cb41489909bce00c9b143d.r2.dev/5.1%20-%20H%C3%A9rouville-Saint-Clair/3.jpg; https://pub-843c46afc4cb41489909bce00c9b143d.r2.dev/5.1%20-%20H%C3%A9rouville-Saint-Clair/4.jpg; https://pub-843c46afc4cb41489909bce00c9b143d.r2.dev/5.11%20-%20H%C3%A9rouville-Saint-Clair/5%20B23B%20-%205372%20-%20GLA-2017.12.04.jpg | AT16: Oui | AU16: Au BP | AV16: Twenty Two
A17: =VLOOKUP(Tableau1[[#This Row],[N° Département]],Feuil1!$C$6:$E$106,3) -> Normandie | B17: =VLOOKUP(Tableau1[[#This Row],[N° Département]],Feuil1!$C$6:$E$106,2) -> Calvados | C17: =LEFT(Tableau1[[#This Row],[Code Postal]],2)*1 -> 14 | D17: 103 Le Val | E17: 14200 | F17: Hérouville-Saint-Clair | G17: =Tableau1[[#This Row],[Rue]]&CHAR(10)&Tableau1[[#This Row],[Code Postal]]&" - "&Tableau1[[#This Row],[Ville]] -> 103 Le Val 14200 - Hérouville-Saint-Clair | H17: https://maps.app.goo.gl/yRNFdK1p6sWPThzm18 | I17: Périphérie | J17: Centre Commercial | K17: / | M17: / | N17: B20 | O17: 210 | P17: / | Q17: / | R17: / | S17: / | T17: =Tableau1[[#This Row],[Loyer €/m²]]*Tableau1[[#This Row],[Surface GLA]] -> 73500 | U17: =IFERROR(Tableau1[[#This Row],[Loyer annuel]]/12,"") -> 6125 | V17: 350 | W17: / | X17: =Tableau1[[#This Row],[Charges €/m²]]*Tableau1[[#This Row],[Surface GLA]] -> 15330 | Y17: =Tableau1[[#This Row],[Charges annuelles]]/12 -> 1277.5 | Z17: 73 | AA17: =IFERROR(Tableau1[[#This Row],[Taxe foncière €/m²]]*Tableau1[[#This Row],[Surface GLA]],) -> 5040 | AB17: 24 | AC17: =IFERROR(Tableau1[[#This Row],[Marketing €/m²]]*Tableau1[[#This Row],[Surface GLA]],) -> 4410 | AD17: 21 | AE17: =IFERROR(Tableau1[[#This Row],[Loyer annuel]]+Tableau1[[#This Row],[Charges annuelles]]+Tableau1[[#This Row],[Taxe foncière]]+Tableau1[[#This Row],[Marketing]],"") -> 98280 | AF17: / | AG17: / | AH17: 0.025 | AI17: En l'état du précédent locataire | AJ17: Non | AK17: Froide | AL17: Basic Fit, Normal, Micromania, Okaïdi, Marionnaud, Promod, Rougegorge, Mcdonald's | AM17: Flux de 4,4M annuel avec un hyper à 60 M€. 73 boutiques dans la Galerie. | AO17: 30% du loyer facial avec un minimum de 15 000 € HT | AP17: 49.205982 | AQ17: -0.327975 | AR17: 5.12 | AS17: https://pub-843c46afc4cb41489909bce00c9b143d.r2.dev/5.1%20-%20H%C3%A9rouville-Saint-Clair/1.jpg; https://pub-843c46afc4cb41489909bce00c9b143d.r2.dev/5.1%20-%20H%C3%A9rouville-Saint-Clair/2.jpg; https://pub-843c46afc4cb41489909bce00c9b143d.r2.dev/5.1%20-%20H%C3%A9rouville-Saint-Clair/3.jpg; https://pub-843c46afc4cb41489909bce00c9b143d.r2.dev/5.1%20-%20H%C3%A9rouville-Saint-Clair/4.jpg; https://pub-843c46afc4cb41489909bce00c9b143d.r2.dev/5.12%20-%20H%C3%A9rouville-Saint-Clair/5%20B20%20-%205372%20-%20GLA-2017.12.04.jpg | AT17: Oui | AU17: Au BP | AV17: Twenty Two
A18: =VLOOKUP(Tableau1[[#This Row],[N° Département]],Feuil1!$C$6:$E$106,3) -> Normandie | B18: =VLOOKUP(Tableau1[[#This Row],[N° Département]],Feuil1!$C$6:$E$106,2) -> Calvados | C18: =LEFT(Tableau1[[#This Row],[Code Postal]],2)*1 -> 14 | D18: 103 Le Val | E18: 14200 | F18: Hérouville-Saint-Clair | G18: =Tableau1[[#This Row],[Rue]]&CHAR(10)&Tableau1[[#This Row],[Code Postal]]&" - "&Tableau1[[#This Row],[Ville]] -> 103 Le Val 14200 - Hérouville-Saint-Clair | H18: https://maps.app.goo.gl/yRNFdK1p6sWPThzm19 | I18: Périphérie | J18: Centre Commercial | K18: / | M18: / | N18: B26B | O18: 30 | P18: / | Q18: / | R18: / | S18: / | T18: =Tableau1[[#This Row],[Loyer €/m²]]*Tableau1[[#This Row],[Surface GLA]] -> 15000 | U18: =IFERROR(Tableau1[[#This Row],[Loyer annuel]]/12,"") -> 1250 | V18: 500 | W18: / | X18: =Tableau1[[#This Row],[Charges €/m²]]*Tableau1[[#This Row],[Surface GLA]] -> 2190 | Y18: =Tableau1[[#This Row],[Charges annuelles]]/12 -> 182.5 | Z18: 73 | AA18: =IFERROR(Tableau1[[#This Row],[Taxe foncière €/m²]]*Tableau1[[#This Row],[Surface GLA]],) -> 720 | AB18: 24 | AC18: =IFERROR(Tableau1[[#This Row],[Marketing €/m²]]*Tableau1[[#This Row],[Surface GLA]],) -> 630 | AD18: 21 | AE18: =IFERROR(Tableau1[[#This Row],[Loyer annuel]]+Tableau1[[#This Row],[Charges annuelles]]+Tableau1[[#This Row],[Taxe foncière]]+Tableau1[[#This Row],[Marketing]],"") -> 18540 | AF18: / | AG18: / | AH18: 0.025 | AI18: En l'état du précédent locataire | AJ18: Oui | AK18: Chaude et froide | AL18: Basic Fit, Normal, Micromania, Okaïdi, Marionnaud, Promod, Rougegorge, Mcdonald's | AM18: Flux de 4,4M annuel avec un hyper à 60 M€. 73 boutiques dans la Galerie. | AO18: 30% du loyer facial avec un minimum de 15 000 € HT | AP18: 49.205712 | AQ18: -0.328139 | AR18: 5.13 | AS18: https://pub-843c46afc4cb41489909bce00c9b143d.r2.dev/5.1%20-%20H%C3%A9rouville-Saint-Clair/1.jpg; https://pub-843c46afc4cb41489909bce00c9b143d.r2.dev/5.1%20-%20H%C3%A9rouville-Saint-Clair/2.jpg; https://pub-843c46afc4cb41489909bce00c9b143d.r2.dev/5.1%20-%20H%C3%A9rouville-Saint-Clair/3.jpg; https://pub-843c46afc4cb41489909bce00c9b143d.r2.dev/5.1%20-%20H%C3%A9rouville-Saint-Clair/4.jpg; https://pub-843c46afc4cb41489909bce00c9b143d.r2.dev/5.13%20-%20H%C3%A9rouville-Saint-Clair/5%20B24%20et%20B26A%20et%20B%20-%205372-GLA-2019.07.12.jpg | AT18: Oui | AU18: Au BP | AV18: Twenty Two
A19: =VLOOKUP(Tableau1[[#This Row],[N° Département]],Feuil1!$C$6:$E$106,3) -> Bretagne | B19: =VLOOKUP(Tableau1[[#This Row],[N° Département]],Feuil1!$C$6:$E$106,2) -> Ille-et-Vilaine | C19: =LEFT(Tableau1[[#This Row],[Code Postal]],2)*1 -> 35 | D19: ZAC de Cap Malo | E19: 35520 | F19: La Mézière | G19: =Tableau1[[#This Row],[Rue]]&CHAR(10)&Tableau1[[#This Row],[Code Postal]]&" - "&Tableau1[[#This Row],[Ville]] -> ZAC de Cap Malo 35520 - La Mézière | H19: https://maps.app.goo.gl/jKvNrbE9PyvENUPV6 | I19: Périphérie | J19: Retail Park | K19: / | M19: / | N19: 1 | O19: 1200 | P19: / | Q19: 2400 | R19: / | S19: / | T19: =Tableau1[[#This Row],[Loyer €/m²]]*Tableau1[[#This Row],[Surface GLA]] -> 120000 | U19: =IFERROR(Tableau1[[#This Row],[Loyer annuel]]/12,"") -> 10000 | V19: 100 | W19: / | X19: =Tableau1[[#This Row],[Charges €/m²]]*Tableau1[[#This Row],[Surface GLA]] -> 30000 | Y19: =Tableau1[[#This Row],[Charges annuelles]]/12 -> 2500 | Z19: 25 | AA19: =IFERROR(Tableau1[[#This Row],[Taxe foncière €/m²]]*Tableau1[[#This Row],[Surface GLA]],) -> 9600 | AB19: 8 | AC19: =IFERROR(Tableau1[[#This Row],[Marketing €/m²]]*Tableau1[[#This Row],[Surface GLA]],) -> 25200 | AD19: 21 | AE19: =IFERROR(Tableau1[[#This Row],[Loyer annuel]]+Tableau1[[#This Row],[Charges annuelles]]+Tableau1[[#This Row],[Taxe foncière]]+Tableau1[[#This Row],[Marketing]],"") -> 184800 | AF19: / | AG19: / | AH19: / | AI19: En l'état du précédent locataire | AJ19: A étudier | AK19: Chaude et froide | AL19: Cash Piscine, Lyre, Kraft, Vib's, Cache Cache, Grain de Malice, Bréal, Canadian Store | AM19: 1 000 places de parking. | AN19: 2 500 € HT | AO19: 30% du loyer facial avec un minimum de 15 000 € HT | AP19: 48.197608 | AQ19: -1.725854 | AR19: 6.1 | AS19: https://pub-843c46afc4cb41489909bce00c9b143d.r2.dev/6.1%20-%20La%20M%C3%A9zi%C3%A8re/1.jpg | AT19: Oui | AU19: Au BP | AV19: Twenty Two
A20: =VLOOKUP(Tableau1[[#This Row],[N° Département]],Feuil1!$C$6:$E$106,3) -> Bretagne | B20: =VLOOKUP(Tableau1[[#This Row],[N° Département]],Feuil1!$C$6:$E$106,2) -> Ille-et-Vilaine | C20: =LEFT(Tableau1[[#This Row],[Code Postal]],2)*1 -> 35 | D20: ZAC de Cap Malo | E20: 35520 | F20: La Mézière | G20: =Tableau1[[#This Row],[Rue]]&CHAR(10)&Tableau1[[#This Row],[Code Postal]]&" - "&Tableau1[[#This Row],[Ville]] -> ZAC de Cap Malo 35520 - La Mézière | H20: https://maps.app.goo.gl/jKvNrbE9PyvENUPV6 | I20: Périphérie | J20: Retail Park | K20: / | M20: / | N20: 2 | O20: 1200 | P20: / | Q20: 2400 | R20: / | S20: / | T20: =Tableau1[[#This Row],[Loyer €/m²]]*Tableau1[[#This Row],[Surface GLA]] -> 120000 | U20: =IFERROR(Tableau1[[#This Row],[Loyer annuel]]/12,"") -> 10000 | V20: 100 | W20: / | X20: =Tableau1[[#This Row],[Charges €/m²]]*Tableau1[[#This Row],[Surface GLA]] -> 30000 | Y20: =Tableau1[[#This Row],[Charges annuelles]]/12 -> 2500 | Z20: 25 | AA20: =IFERROR(Tableau1[[#This Row],[Taxe foncière €/m²]]*Tableau1[[#This Row],[Surface GLA]],) -> 9600 | AB20: 8 | AC20: =IFERROR(Tableau1[[#This Row],[Marketing €/m²]]*Tableau1[[#This Row],[Surface GLA]],) -> 0 | AD20: / | AE20: =IFERROR(Tableau1[[#This Row],[Loyer annuel]]+Tableau1[[#This Row],[Charges annuelles]]+Tableau1[[#This Row],[Taxe foncière]]+Tableau1[[#This Row],[Marketing]],"") -> 159600 | AF20: / | AG20: / | AH20: / | AI20: En l'état du précédent locataire | AJ20: A étudier | AK20: Chaude et froide | AL20: Cash Piscine, Lyre, Kraft, Vib's, Cache Cache, Grain de Malice, Bréal, Canadian Store | AM20: 1 000 places de parking. | AN20: 2 500 € HT | AO20: 30% du loyer facial avec un minimum de 15 000 € HT | AP20: 48.197772 | AQ20: -1.725999 | AR20: 6.2 | AS20: https://pub-843c46afc4cb41489909bce00c9b143d.r2.dev/6.2%20-%20La%20M%C3%A9zi%C3%A8re/1.jpg | AT20: Oui | AU20: Au BP | AV20: Twenty Two
A21: =VLOOKUP(Tableau1[[#This Row],[N° Département]],Feuil1!$C$6:$E$106,3) -> Bretagne | B21: =VLOOKUP(Tableau1[[#This Row],[N° Département]],Feuil1!$C$6:$E$106,2) -> Ille-et-Vilaine | C21: =LEFT(Tableau1[[#This Row],[Code Postal]],2)*1 -> 35 | D21: ZAC de Cap Malo | E21: 35520 | F21: La Mézière | G21: =Tableau1[[#This Row],[Rue]]&CHAR(10)&Tableau1[[#This Row],[Code Postal]]&" - "&Tableau1[[#This Row],[Ville]] -> ZAC de Cap Malo 35520 - La Mézière | H21: https://maps.app.goo.gl/jKvNrbE9PyvENUPV6 | I21: Périphérie | J21: Retail Park | K21: / | M21: / | N21: 3 | O21: 549 | P21: / | Q21: 1051 | R21: / | S21: / | T21: =Tableau1[[#This Row],[Loyer €/m²]]*Tableau1[[#This Row],[Surface GLA]] -> 82350 | U21: =IFERROR(Tableau1[[#This Row],[Loyer annuel]]/12,"") -> 6862.5 | V21: 150 | W21: / | X21: =Tableau1[[#This Row],[Charges €/m²]]*Tableau1[[#This Row],[Surface GLA]] -> 13725 | Y21: =Tableau1[[#This Row],[Charges annuelles]]/12 -> 1143.75 | Z21: 25 | AA21: =IFERROR(Tableau1[[#This Row],[Taxe foncière €/m²]]*Tableau1[[#This Row],[Surface GLA]],) -> 4392 | AB21: 8 | AC21: =IFERROR(Tableau1[[#This Row],[Marketing €/m²]]*Tableau1[[#This Row],[Surface GLA]],) -> 0 | AD21: / | AE21: =IFERROR(Tableau1[[#This Row],[Loyer annuel]]+Tableau1[[#This Row],[Charges annuelles]]+Tableau1[[#This Row],[Taxe foncière]]+Tableau1[[#This Row],[Marketing]],"") -> 100467 | AF21: / | AG21: / | AH21: / | AI21: En l'état du précédent locataire | AJ21: A étudier | AK21: Chaude et froide | AL21: Cash Piscine, Lyre, Kraft, Vib's, Cache Cache, Grain de Malice, Bréal, Canadian Store | AM21: 1 000 places de parking. | AN21: 2 500 € HT | AO21: 30% du loyer facial avec un minimum de 15 000 € HT | AP21: 48.198039 | AQ21: -1.726240 | AR21: 6.3 | AS21: https://pub-843c46afc4cb41489909bce00c9b143d.r2.dev/6.3%20-%20La%20M%C3%A9zi%C3%A8re/1.jpg | AT21: Oui | AU21: Au BP | AV21: Twenty Two
A22: =VLOOKUP(Tableau1[[#This Row],[N° Département]],Feuil1!$C$6:$E$106,3) -> Bretagne | B22: =VLOOKUP(Tableau1[[#This Row],[N° Département]],Feuil1!$C$6:$E$106,2) -> Ille-et-Vilaine | C22: =LEFT(Tableau1[[#This Row],[Code Postal]],2)*1 -> 35 | D22: ZAC de Cap Malo | E22: 35520 | F22: La Mézière | G22: =Tableau1[[#This Row],[Rue]]&CHAR(10)&Tableau1[[#This Row],[Code Postal]]&" - "&Tableau1[[#This Row],[Ville]] -> ZAC de Cap Malo 35520 - La Mézière | H22: https://maps.app.goo.gl/jKvNrbE9PyvENUPV6 | I22: Périphérie | J22: Retail Park | K22: / | M22: / | N22: 4 | O22: 502 | P22: / | Q22: 1051 | R22: / | S22: / | T22: =Tableau1[[#This Row],[Loyer €/m²]]*Tableau1[[#This Row],[Surface GLA]] -> 75300 | U22: =IFERROR(Tableau1[[#This Row],[Loyer annuel]]/12,"") -> 6275 | V22: 150 | W22: / | X22: =Tableau1[[#This Row],[Charges €/m²]]*Tableau1[[#This Row],[Surface GLA]] -> 12550 | Y22: =Tableau1[[#This Row],[Charges annuelles]]/12 -> 1045.8333 | Z22: 25 | AA22: =IFERROR(Tableau1[[#This Row],[Taxe foncière €/m²]]*Tableau1[[#This Row],[Surface GLA]],) -> 4016 | AB22: 8 | AC22: =IFERROR(Tableau1[[#This Row],[Marketing €/m²]]*Tableau1[[#This Row],[Surface GLA]],) -> 0 | AD22: / | AE22: =IFERROR(Tableau1[[#This Row],[Loyer annuel]]+Tableau1[[#This Row],[Charges annuelles]]+Tableau1[[#This Row],[Taxe foncière]]+Tableau1[[#This Row],[Marketing]],"") -> 91866 | AF22: / | AG22: / | AH22: / | AI22: En l'état du précédent locataire | AJ22: A étudier | AK22: Chaude et froide | AL22: Cash Piscine, Lyre, Kraft, Vib's, Cache Cache, Grain de Malice, Bréal, Canadian Store | AM22: 1 000 places de parking. | AN22: 2 500 € HT | AO22: 30% du loyer facial avec un minimum de 15 000 € HT | AP22: 48.198166 | AQ22: -1.726390 | AR22: 6.4 | AS22: https://pub-843c46afc4cb41489909bce00c9b143d.r2.dev/6.4%20-%20La%20M%C3%A9zi%C3%A8re/1.jpg | AT22: Oui | AU22: Au BP | AV22: Twenty Two
A23: =VLOOKUP(Tableau1[[#This Row],[N° Département]],Feuil1!$C$6:$E$106,3) -> Bretagne | B23: =VLOOKUP(Tableau1[[#This Row],[N° Département]],Feuil1!$C$6:$E$106,2) -> Ille-et-Vilaine | C23: =LEFT(Tableau1[[#This Row],[Code Postal]],2)*1 -> 35 | D23: ZAC de Cap Malo | E23: 35520 | F23: La Mézière | G23: =Tableau1[[#This Row],[Rue]]&CHAR(10)&Tableau1[[#This Row],[Code Postal]]&" - "&Tableau1[[#This Row],[Ville]] -> ZAC de Cap Malo 35520 - La Mézière | H23: https://maps.app.goo.gl/jKvNrbE9PyvENUPV6 | I23: Périphérie | J23: Retail Park | K23: / | M23: / | N23: 5 | O23: 250 | P23: / | Q23: 514 | R23: / | S23: / | T23: =Tableau1[[#This Row],[Loyer €/m²]]*Tableau1[[#This Row],[Surface GLA]] -> 50000 | U23: =IFERROR(Tableau1[[#This Row],[Loyer annuel]]/12,"") -> 4166.6667 | V23: 200 | W23: / | X23: =Tableau1[[#This Row],[Charges €/m²]]*Tableau1[[#This Row],[Surface GLA]] -> 6250 | Y23: =Tableau1[[#This Row],[Charges annuelles]]/12 -> 520.83333 | Z23: 25 | AA23: =IFERROR(Tableau1[[#This Row],[Taxe foncière €/m²]]*Tableau1[[#This Row],[Surface GLA]],) -> 2000 | AB23: 8 | AC23: =IFERROR(Tableau1[[#This Row],[Marketing €/m²]]*Tableau1[[#This Row],[Surface GLA]],) -> 0 | AD23: / | AE23: =IFERROR(Tableau1[[#This Row],[Loyer annuel]]+Tableau1[[#This Row],[Charges annuelles]]+Tableau1[[#This Row],[Taxe foncière]]+Tableau1[[#This Row],[Marketing]],"") -> 58250 | AF23: / | AG23: / | AH23: / | AI23: En l'état du précédent locataire | AJ23: A étudier | AK23: Chaude et froide | AL23: Cash Piscine, Lyre, Kraft, Vib's, Cache Cache, Grain de Malice, Bréal, Canadian Store | AM23: 1 000 places de parking. | AN23: 2 500 € HT | AO23: 30% du loyer facial avec un minimum de 15 000 € HT | AP23: 48.198348 | AQ23: -1.726557 | AR23: 6.5 | AS23: https://pub-843c46afc4cb41489909bce00c9b143d.r2.dev/6.5%20-%20La%20M%C3%A9zi%C3%A8re/1.jpg | AT23: Oui | AU23: Au BP | AV23: Twenty Two
A24: =VLOOKUP(Tableau1[[#This Row],[N° Département]],Feuil1!$C$6:$E$106,3) -> Bretagne | B24: =VLOOKUP(Tableau1[[#This Row],[N° Département]],Feuil1!$C$6:$E$106,2) -> Ille-et-Vilaine | C24: =LEFT(Tableau1[[#This Row],[Code Postal]],2)*1 -> 35 | D24: ZAC de Cap Malo | E24: 35520 | F24: La Mézière | G24: =Tableau1[[#This Row],[Rue]]&CHAR(10)&Tableau1[[#This Row],[Code Postal]]&" - "&Tableau1[[#This Row],[Ville]] -> ZAC de Cap Malo 35520 - La Mézière | H24: https://maps.app.goo.gl/jKvNrbE9PyvENUPV6 | I24: Périphérie | J24: Retail Park | K24: / | M24: / | N24: 6 | O24: 264 | P24: / | Q24: 514 | R24: / | S24: / | T24: =Tableau1[[#This Row],[Loyer €/m²]]*Tableau1[[#This Row],[Surface GLA]] -> 52800 | U24: =IFERROR(Tableau1[[#This Row],[Loyer annuel]]/12,"") -> 4400 | V24: 200 | W24: / | X24: =Tableau1[[#This Row],[Charges €/m²]]*Tableau1[[#This Row],[Surface GLA]] -> 6600 | Y24: =Tableau1[[#This Row],[Charges annuelles]]/12 -> 550 | Z24: 25 | AA24: =IFERROR(Tableau1[[#This Row],[Taxe foncière €/m²]]*Tableau1[[#This Row],[Surface GLA]],) -> 2112 | AB24: 8 | AC24: =IFERROR(Tableau1[[#This Row],[Marketing €/m²]]*Tableau1[[#This Row],[Surface GLA]],) -> 0 | AD24: / | AE24: =IFERROR(Tableau1[[#This Row],[Loyer annuel]]+Tableau1[[#This Row],[Charges annuelles]]+Tableau1[[#This Row],[Taxe foncière]]+Tableau1[[#This Row],[Marketing]],"") -> 61512 | AF24: / | AG24: / | AH24: / | AI24: En l'état du précédent locataire | AJ24: A étudier | AK24: Chaude et froide | AL24: Cash Piscine, Lyre, Kraft, Vib's, Cache Cache, Grain de Malice, Bréal, Canadian Store | AM24: 1 000 places de parking. | AN24: 2 500 € HT | AO24: 30% du loyer facial avec un minimum de 15 000 € HT | AP24: 48.198452 | AQ24: -1.726667 | AR24: 6.6 | AS24: https://pub-843c46afc4cb41489909bce00c9b143d.r2.dev/6.6%20-%20La%20M%C3%A9zi%C3%A8re/1.jpg | AT24: Oui | AU24: Au BP | AV24: Twenty Two
A25: =VLOOKUP(Tableau1[[#This Row],[N° Département]],Feuil1!$C$6:$E$106,3) -> Bretagne | B25: =VLOOKUP(Tableau1[[#This Row],[N° Département]],Feuil1!$C$6:$E$106,2) -> Ille-et-Vilaine | C25: =LEFT(Tableau1[[#This Row],[Code Postal]],2)*1 -> 35 | D25: ZAC de Cap Malo | E25: 35520 | F25: La Mézière | G25: =Tableau1[[#This Row],[Rue]]&CHAR(10)&Tableau1[[#This Row],[Code Postal]]&" - "&Tableau1[[#This Row],[Ville]] -> ZAC de Cap Malo 35520 - La Mézière | H25: https://maps.app.goo.gl/jKvNrbE9PyvENUPV6 | I25: Périphérie | J25: Retail Park | K25: / | M25: / | N25: 7 | O25: 486 | P25: / | Q25: / | R25: / | S25: / | T25: =Tableau1[[#This Row],[Loyer €/m²]]*Tableau1[[#This Row],[Surface GLA]] -> 72900 | U25: =IFERROR(Tableau1[[#This Row],[Loyer annuel]]/12,"") -> 6075 | V25: 150 | W25: / | X25: =Tableau1[[#This Row],[Charges €/m²]]*Tableau1[[#This Row],[Surface GLA]] -> 12150 | Y25: =Tableau1[[#This Row],[Charges annuelles]]/12 -> 1012.5 | Z25: 25 | AA25: =IFERROR(Tableau1[[#This Row],[Taxe foncière €/m²]]*Tableau1[[#This Row],[Surface GLA]],) -> 3888 | AB25: 8 | AC25: =IFERROR(Tableau1[[#This Row],[Marketing €/m²]]*Tableau1[[#This Row],[Surface GLA]],) -> 0 | AD25: / | AE25: =IFERROR(Tableau1[[#This Row],[Loyer annuel]]+Tableau1[[#This Row],[Charges annuelles]]+Tableau1[[#This Row],[Taxe foncière]]+Tableau1[[#This Row],[Marketing]],"") -> 88938 | AF25: / | AG25: / | AH25: / | AI25: En l'état du précédent locataire | AJ25: A étudier | AK25: Chaude et froide | AL25: Cash Piscine, Lyre, Kraft, Vib's, Cache Cache, Grain de Malice, Bréal, Canadian Store | AM25: 1 000 places de parking. | AN25: 2 500 € HT | AO25: 30% du loyer facial avec un minimum de 15 000 € HT | AP25: 48.198584 | AQ25: -1.726814 | AR25: 6.7 | AS25: https://pub-843c46afc4cb41489909bce00c9b143d.r2.dev/6.7%20-%20La%20M%C3%A9zi%C3%A8re/1.jpg | AT25: Oui | AU25: Au BP | AV25: Twenty Two
A26: =VLOOKUP(Tableau1[[#This Row],[N° Département]],Feuil1!$C$6:$E$106,3) -> Bretagne | B26: =VLOOKUP(Tableau1[[#This Row],[N° Département]],Feuil1!$C$6:$E$106,2) -> Ille-et-Vilaine | C26: =LEFT(Tableau1[[#This Row],[Code Postal]],2)*1 -> 35 | D26: ZAC de Cap Malo | E26: 35520 | F26: La Mézière | G26: =Tableau1[[#This Row],[Rue]]&CHAR(10)&Tableau1[[#This Row],[Code Postal]]&" - "&Tableau1[[#This Row],[Ville]] -> ZAC de Cap Malo 35520 - La Mézière | H26: https://maps.app.goo.gl/jKvNrbE9PyvENUPV6 | I26: Périphérie | J26: Retail Park | K26: / | M26: / | N26: 8 | O26: 267 | P26: / | Q26: 1060 | R26: / | S26: / | T26: =Tableau1[[#This Row],[Loyer €/m²]]*Tableau1[[#This Row],[Surface GLA]] -> 53400 | U26: =IFERROR(Tableau1[[#This Row],[Loyer annuel]]/12,"") -> 4450 | V26: 200 | W26: / | X26: =Tableau1[[#This Row],[Charges €/m²]]*Tableau1[[#This Row],[Surface GLA]] -> 6675 | Y26: =Tableau1[[#This Row],[Charges annuelles]]/12 -> 556.25 | Z26: 25 | AA26: =IFERROR(Tableau1[[#This Row],[Taxe foncière €/m²]]*Tableau1[[#This Row],[Surface GLA]],) -> 2136 | AB26: 8 | AC26: =IFERROR(Tableau1[[#This Row],[Marketing €/m²]]*Tableau1[[#This Row],[Surface GLA]],) -> 0 | AD26: / | AE26: =IFERROR(Tableau1[[#This Row],[Loyer annuel]]+Tableau1[[#This Row],[Charges annuelles]]+Tableau1[[#This Row],[Taxe foncière]]+Tableau1[[#This Row],[Marketing]],"") -> 62211 | AF26: / | AG26: / | AH26: / | AI26: En l'état du précédent locataire | AJ26: A étudier | AK26: Chaude et froide | AL26: Cash Piscine, Lyre, Kraft, Vib's, Cache Cache, Grain de Malice, Bréal, Canadian Store | AM26: 1 000 places de parking. | AN26: 2 500 € HT | AO26: 30% du loyer facial avec un minimum de 15 000 € HT | AP26: 48.198731 | AQ26: -1.726769 | AR26: 6.8 | AS26: https://pub-843c46afc4cb41489909bce00c9b143d.r2.dev/6.8%20-%20La%20M%C3%A9zi%C3%A8re/1.jpg | AT26: Oui | AU26: Au BP | AV26: Twenty Two
A27: =VLOOKUP(Tableau1[[#This Row],[N° Département]],Feuil1!$C$6:$E$106,3) -> Bretagne | B27: =VLOOKUP(Tableau1[[#This Row],[N° Département]],Feuil1!$C$6:$E$106,2) -> Ille-et-Vilaine | C27: =LEFT(Tableau1[[#This Row],[Code Postal]],2)*1 -> 35 | D27: ZAC de Cap Malo | E27: 35520 | F27: La Mézière | G27: =Tableau1[[#This Row],[Rue]]&CHAR(10)&Tableau1[[#This Row],[Code Postal]]&" - "&Tableau1[[#This Row],[Ville]] -> ZAC de Cap Malo 35520 - La Mézière | H27: https://maps.app.goo.gl/jKvNrbE9PyvENUPV6 | I27: Périphérie | J27: Retail Park | K27: / | M27: / | N27: 9 | O27: 321 | P27: / | Q27: 1060 | R27: / | S27: / | T27: =Tableau1[[#This Row],[Loyer €/m²]]*Tableau1[[#This Row],[Surface GLA]] -> 48150 | U27: =IFERROR(Tableau1[[#This Row],[Loyer annuel]]/12,"") -> 4012.5 | V27: 150 | W27: / | X27: =Tableau1[[#This Row],[Charges €/m²]]*Tableau1[[#This Row],[Surface GLA]] -> 8025 | Y27: =Tableau1[[#This Row],[Charges annuelles]]/12 -> 668.75 | Z27: 25 | AA27: =IFERROR(Tableau1[[#This Row],[Taxe foncière €/m²]]*Tableau1[[#This Row],[Surface GLA]],) -> 2568 | AB27: 8 | AC27: =IFERROR(Tableau1[[#This Row],[Marketing €/m²]]*Tableau1[[#This Row],[Surface GLA]],) -> 0 | AD27: / | AE27: =IFERROR(Tableau1[[#This Row],[Loyer annuel]]+Tableau1[[#This Row],[Charges annuelles]]+Tableau1[[#This Row],[Taxe foncière]]+Tableau1[[#This Row],[Marketing]],"") -> 58743 | AF27: / | AG27: / | AH27: / | AI27: En l'état du précédent locataire | AJ27: A étudier | AK27: Chaude et froide | AL27: Cash Piscine, Lyre, Kraft, Vib's, Cache Cache, Grain de Malice, Bréal, Canadian Store | AM27: 1 000 places de parking. | AN27: 2 500 € HT | AO27: 30% du loyer facial avec un minimum de 15 000 € HT | AP27: 48.198775 | AQ27: -1.726648 | AR27: 6.9 | AS27: https://pub-843c46afc4cb41489909bce00c9b143d.r2.dev/6.9%20-%20La%20M%C3%A9zi%C3%A8re/1.jpg | AT27: Oui | AU27: Au BP | AV27: Twenty Two
A28: =VLOOKUP(Tableau1[[#This Row],[N° Département]],Feuil1!$C$6:$E$106,3) -> Bretagne | B28: =VLOOKUP(Tableau1[[#This Row],[N° Département]],Feuil1!$C$6:$E$106,2) -> Ille-et-Vilaine | C28: =LEFT(Tableau1[[#This Row],[Code Postal]],2)*1 -> 35 | D28: ZAC de Cap Malo | E28: 35520 | F28: La Mézière | G28: =Tableau1[[#This Row],[Rue]]&CHAR(10)&Tableau1[[#This Row],[Code Postal]]&" - "&Tableau1[[#This Row],[Ville]] -> ZAC de Cap Malo 35520 - La Mézière | H28: https://maps.app.goo.gl/jKvNrbE9PyvENUPV6 | I28: Périphérie | J28: Retail Park | K28: / | M28: / | N28: 10 | O28: 472 | P28: / | Q28: 1060 | R28: / | S28: / | T28: =Tableau1[[#This Row],[Loyer €/m²]]*Tableau1[[#This Row],[Surface GLA]] -> 70800 | U28: =IFERROR(Tableau1[[#This Row],[Loyer annuel]]/12,"") -> 5900 | V28: 150 | W28: / | X28: =Tableau1[[#This Row],[Charges €/m²]]*Tableau1[[#This Row],[Surface GLA]] -> 11800 | Y28: =Tableau1[[#This Row],[Charges annuelles]]/12 -> 983.33333 | Z28: 25 | AA28: =IFERROR(Tableau1[[#This Row],[Taxe foncière €/m²]]*Tableau1[[#This Row],[Surface GLA]],) -> 3776 | AB28: 8 | AC28: =IFERROR(Tableau1[[#This Row],[Marketing €/m²]]*Tableau1[[#This Row],[Surface GLA]],) -> 0 | AD28: / | AE28: =IFERROR(Tableau1[[#This Row],[Loyer annuel]]+Tableau1[[#This Row],[Charges annuelles]]+Tableau1[[#This Row],[Taxe foncière]]+Tableau1[[#This Row],[Marketing]],"") -> 86376 | AF28: / | AG28: / | AH28: / | AI28: En l'état du précédent locataire | AJ28: A étudier | AK28: Chaude et froide | AL28: Cash Piscine, Lyre, Kraft, Vib's, Cache Cache, Grain de Malice, Bréal, Canadian Store | AM28: 1 000 places de parking. | AN28: 2 500 € HT | AO28: 30% du loyer facial avec un minimum de 15 000 € HT | AP28: 48.198827 | AQ28: -1.726519 | AR28: 6.10 | AS28: https://pub-843c46afc4cb41489909bce00c9b143d.r2.dev/6.10%20-%20La%20M%C3%A9zi%C3%A8re/1.jpg | AT28: Oui | AU28: Au BP | AV28: Twenty Two
